Database manager initialized.
logging in using static token
[31m[1mWARNING: This is a development server. Do not use it in a production deployment. Use a production WSGI server instead.[0m
 * Running on all addresses (0.0.0.0)
 * Running on http://127.0.0.1:8080
 * Running on http://192.168.0.5:8080
[33mPress CTRL+C to quit[0m
Shard ID None has connected to Gateway (Session ID: 9dff88e379aec93c3de849bce7c3c76c).
Bot logged in as Betterment#4897
Bot ID: 1392030134373974066
TeamsCog loaded successfully.
Loaded cog: cogs.teams.cog
Connected to 1 guilds
Synced 6 global commands
Successfully deleted team 'Team 3' and its resources.
Error in 'Reflect & Form Teams' button: 'TeamsCog' object has no attribute '_build_reflection_embed'
Traceback (most recent call last):
  File "d:\Home\Documents\Programming\Python\Developer Mode\Discord\Betterment\Bot\cogs\teams\ui\buttons.py", line 156, in callback
    embed = self.cog._build_reflection_embed(report)
            ^^^^^^^^^^^^^^^^^^^^^^^^^^^^^^^^
AttributeError: 'TeamsCog' object has no attribute '_build_reflection_embed'
Error in 'Fetch Data' button: 'coroutine' object is not subscriptable
Traceback (most recent call last):
  File "d:\Home\Documents\Programming\Python\Developer Mode\Discord\Betterment\Bot\cogs\teams\ui\buttons.py", line 180, in callback
    value=str(results['registered']),
              ~~~~~~~^^^^^^^^^^^^^^
TypeError: 'coroutine' object is not subscriptable
Database manager initialized.
logging in using static token
[31m[1mWARNING: This is a development server. Do not use it in a production deployment. Use a production WSGI server instead.[0m
 * Running on all addresses (0.0.0.0)
 * Running on http://127.0.0.1:8080
 * Running on http://192.168.0.5:8080
[33mPress CTRL+C to quit[0m
Shard ID None has connected to Gateway (Session ID: ae3fe00c349c819f11402240d86cdb33).
Bot logged in as Betterment#4897
Bot ID: 1392030134373974066
TeamsCog loaded successfully.
Loaded cog: cogs.teams.cog
Connected to 1 guilds
Synced 6 global commands
An unhandled command error occurred in TeamsCog: Command 'add_members' raised an exception: ValueError: not enough values to unpack (expected 4, got 3)
Traceback (most recent call last):
  File "C:\Users\Joseph\AppData\Local\Programs\Python\Python313\Lib\site-packages\discord\app_commands\commands.py", line 857, in _do_call
    return await self._callback(self.binding, interaction, **params)  # type: ignore
           ^^^^^^^^^^^^^^^^^^^^^^^^^^^^^^^^^^^^^^^^^^^^^^^^^^^^^^^^^
  File "d:\Home\Documents\Programming\Python\Developer Mode\Discord\Betterment\Bot\cogs\teams\permissions.py", line 69, in wrapper
    return await func(*args, **kwargs)
           ^^^^^^^^^^^^^^^^^^^^^^^^^^^
  File "d:\Home\Documents\Programming\Python\Developer Mode\Discord\Betterment\Bot\cogs\teams\cog.py", line 137, in add_members
    added_members, existing_members, invalid_members, in_other_teams = await self.team_manager.add_members_to_team(
    ^^^^^^^^^^^^^^^^^^^^^^^^^^^^^^^^^^^^^^^^^^^^^^^^^^^^^^^^^^^^^^^^
ValueError: not enough values to unpack (expected 4, got 3)

The above exception was the direct cause of the following exception:

Traceback (most recent call last):
  File "C:\Users\Joseph\AppData\Local\Programs\Python\Python313\Lib\site-packages\discord\app_commands\tree.py", line 1310, in _call
    await command._invoke_with_namespace(interaction, namespace)
  File "C:\Users\Joseph\AppData\Local\Programs\Python\Python313\Lib\site-packages\discord\app_commands\commands.py", line 883, in _invoke_with_namespace
    return await self._do_call(interaction, transformed_values)
           ^^^^^^^^^^^^^^^^^^^^^^^^^^^^^^^^^^^^^^^^^^^^^^^^^^^^
  File "C:\Users\Joseph\AppData\Local\Programs\Python\Python313\Lib\site-packages\discord\app_commands\commands.py", line 876, in _do_call
    raise CommandInvokeError(self, e) from e
discord.app_commands.errors.CommandInvokeError: Command 'add_members' raised an exception: ValueError: not enough values to unpack (expected 4, got 3)
Database manager initialized.
logging in using static token
[31m[1mWARNING: This is a development server. Do not use it in a production deployment. Use a production WSGI server instead.[0m
 * Running on all addresses (0.0.0.0)
 * Running on http://127.0.0.1:8080
 * Running on http://192.168.0.5:8080
[33mPress CTRL+C to quit[0m
Shard ID None has connected to Gateway (Session ID: 3ac0aa40f2a4e6296c45501a859802e0).
Bot logged in as Betterment#4897
Bot ID: 1392030134373974066
TeamsCog loaded successfully.
Loaded cog: cogs.teams.cog
Connected to 1 guilds
Synced 6 global commands
Database manager initialized.
logging in using static token
[31m[1mWARNING: This is a development server. Do not use it in a production deployment. Use a production WSGI server instead.[0m
 * Running on all addresses (0.0.0.0)
 * Running on http://127.0.0.1:8080
 * Running on http://192.168.0.5:8080
[33mPress CTRL+C to quit[0m
Shard ID None has connected to Gateway (Session ID: e1b5a676e5d0e62b056e7194791bb68b).
Bot logged in as Betterment#4897
Bot ID: 1392030134373974066
TeamsCog loaded successfully.
Loaded cog: cogs.teams.cog
Connected to 1 guilds
Synced 6 global commands
Database manager initialized.
logging in using static token
[31m[1mWARNING: This is a development server. Do not use it in a production deployment. Use a production WSGI server instead.[0m
 * Running on all addresses (0.0.0.0)
 * Running on http://127.0.0.1:8080
 * Running on http://192.168.0.5:8080
[33mPress CTRL+C to quit[0m
Shard ID None has connected to Gateway (Session ID: ec42e52a8df554a4e6b8bd4422433669).
Bot logged in as Betterment#4897
Bot ID: 1392030134373974066
TeamsCog loaded successfully.
Loaded cog: cogs.teams.cog
Connected to 1 guilds
Synced 6 global commands
Ignoring exception in view <UnregisteredMemberDropdownView timeout=180 children=1> for item <UnregisteredMemberDropdown placeholder='Select an unassigned member...' min_values=1 max_values=1 disabled=False>
Traceback (most recent call last):
  File "C:\Users\Joseph\AppData\Local\Programs\Python\Python313\Lib\site-packages\discord\ui\view.py", line 435, in _scheduled_task
    await item.callback(interaction)
  File "d:\Home\Documents\Programming\Python\Developer Mode\Discord\Betterment\Bot\cogs\teams\ui\views.py", line 147, in callback
    member_profile = await self.cog.team_manager.member_service.get_unassigned_member_profile(interaction.guild_id, selected_user_id)
                           ^^^^^^^^^^^^^^^^^^^^^^^^^^^^^^^^^^^^^^^^^^^^^^^^^^^^^^^^^^^^^^^^^^
AttributeError: 'TeamMemberService' object has no attribute 'get_unassigned_member_profile'
==================================================
üöÄ STARTING HIERARCHICAL TEAM FORMATION
==================================================
üå± Initializing with 0 leaders and 3 members.
Phase 1: Clustering members by timezone...
-> Found 1 distinct timezone groups.
Phase 2: Clustering by category...
üéØ Initial Clustering Complete: 0 teams created, 3 members initially unassigned.
Phase 4: Reassigning 3 orphaned members...
ü§ù Orphan Reassignment Complete: 0 members placed. 3 remain unassigned.
üö® Final Unassigned Members: ['Luna', 'ùêë ùêò ùêé', 'Lotus ü™∑']
==================================================
‚úÖ TEAM FORMATION PROCESS COMPLETE
==================================================
Database manager initialized.
logging in using static token
[31m[1mWARNING: This is a development server. Do not use it in a production deployment. Use a production WSGI server instead.[0m
 * Running on all addresses (0.0.0.0)
 * Running on http://127.0.0.1:8080
 * Running on http://192.168.0.5:8080
[33mPress CTRL+C to quit[0m
Shard ID None has connected to Gateway (Session ID: bfeacbf9a601a44341e5a7ea7f42647a).
Bot logged in as Betterment#4897
Bot ID: 1392030134373974066
TeamsCog loaded successfully.
Loaded cog: cogs.teams.cog
Connected to 1 guilds
Synced 6 global commands
Ignoring exception in view <TeamRecommendationView timeout=180 children=1> for item <TeamRecommendationDropdown placeholder='Choose a team to assign the member to...' min_values=1 max_values=1 disabled=True>
Traceback (most recent call last):
  File "C:\Users\Joseph\AppData\Local\Programs\Python\Python313\Lib\site-packages\discord\ui\view.py", line 435, in _scheduled_task
    await item.callback(interaction)
  File "d:\Home\Documents\Programming\Python\Developer Mode\Discord\Betterment\Bot\cogs\teams\ui\views.py", line 193, in callback
    await self.cog.panel_manager.refrech_team_panel(interaction.guild.id)
          ^^^^^^^^^^^^^^^^^^^^^^^^^^^^^^^^^^^^^^^^^
AttributeError: 'PanelManager' object has no attribute 'refrech_team_panel'. Did you mean: 'refresh_team_panel'?
Database manager initialized.
logging in using static token
[31m[1mWARNING: This is a development server. Do not use it in a production deployment. Use a production WSGI server instead.[0m
 * Running on all addresses (0.0.0.0)
 * Running on http://127.0.0.1:8080
 * Running on http://192.168.0.5:8080
[33mPress CTRL+C to quit[0m
Shard ID None has connected to Gateway (Session ID: 238c7c3e0f087d52cdbe5103a1b4c7dd).
Bot logged in as Betterment#4897
Bot ID: 1392030134373974066
TeamsCog loaded successfully.
Loaded cog: cogs.teams.cog
Connected to 1 guilds
Synced 6 global commands
Database manager initialized.
logging in using static token
[31m[1mWARNING: This is a development server. Do not use it in a production deployment. Use a production WSGI server instead.[0m
 * Running on all addresses (0.0.0.0)
 * Running on http://127.0.0.1:8080
 * Running on http://192.168.0.5:8080
[33mPress CTRL+C to quit[0m
Shard ID None has connected to Gateway (Session ID: 54876dd59d9f63841cc2ca9d531965db).
Bot logged in as Betterment#4897
Bot ID: 1392030134373974066
Failed to load cog cogs.teams.cog: Extension 'cogs.teams.cog' raised an error: ImportError: cannot import name 'is_marathon_active' from 'cogs.teams.services.team_service' (d:\Home\Documents\Programming\Python\Developer Mode\Discord\Betterment\Bot\cogs\teams\services\team_service.py)
Traceback (most recent call last):
  File "C:\Users\Joseph\AppData\Local\Programs\Python\Python313\Lib\site-packages\discord\ext\commands\bot.py", line 951, in _load_from_module_spec
    spec.loader.exec_module(lib)  # type: ignore
    ~~~~~~~~~~~~~~~~~~~~~~~^^^^^
  File "<frozen importlib._bootstrap_external>", line 1026, in exec_module
  File "<frozen importlib._bootstrap>", line 488, in _call_with_frames_removed
  File "d:\Home\Documents\Programming\Python\Developer Mode\Discord\Betterment\Bot\cogs\teams\cog.py", line 7, in <module>
    from .services.team_manager import TeamManager
  File "d:\Home\Documents\Programming\Python\Developer Mode\Discord\Betterment\Bot\cogs\teams\services\team_manager.py", line 11, in <module>
    from ..services.team_formation_service import TeamFormationService
  File "d:\Home\Documents\Programming\Python\Developer Mode\Discord\Betterment\Bot\cogs\teams\services\team_formation_service.py", line 6, in <module>
    from .team_service import is_marathon_active
ImportError: cannot import name 'is_marathon_active' from 'cogs.teams.services.team_service' (d:\Home\Documents\Programming\Python\Developer Mode\Discord\Betterment\Bot\cogs\teams\services\team_service.py)

The above exception was the direct cause of the following exception:

Traceback (most recent call last):
  File "d:\Home\Documents\Programming\Python\Developer Mode\Discord\Betterment\Bot\main.py", line 56, in load_cogs
    await bot.load_extension(cog_name)
  File "C:\Users\Joseph\AppData\Local\Programs\Python\Python313\Lib\site-packages\discord\ext\commands\bot.py", line 1029, in load_extension
    await self._load_from_module_spec(spec, name)
  File "C:\Users\Joseph\AppData\Local\Programs\Python\Python313\Lib\site-packages\discord\ext\commands\bot.py", line 954, in _load_from_module_spec
    raise errors.ExtensionFailed(key, e) from e
discord.ext.commands.errors.ExtensionFailed: Extension 'cogs.teams.cog' raised an error: ImportError: cannot import name 'is_marathon_active' from 'cogs.teams.services.team_service' (d:\Home\Documents\Programming\Python\Developer Mode\Discord\Betterment\Bot\cogs\teams\services\team_service.py)
Connected to 1 guilds
Synced 0 global commands
Database manager initialized.
logging in using static token
[31m[1mWARNING: This is a development server. Do not use it in a production deployment. Use a production WSGI server instead.[0m
 * Running on all addresses (0.0.0.0)
 * Running on http://127.0.0.1:8080
 * Running on http://192.168.0.5:8080
[33mPress CTRL+C to quit[0m
Shard ID None has connected to Gateway (Session ID: 1ef7f7cd23de1c16e560750095fe7fef).
Bot logged in as Betterment#4897
Bot ID: 1392030134373974066
TeamsCog loaded successfully.
Loaded cog: cogs.teams.cog
Connected to 1 guilds
Synced 6 global commands
==================================================
üöÄ STARTING HIERARCHICAL TEAM FORMATION
==================================================
üå± Initializing with 1 leaders and 4 members.
Phase 1: Clustering members by timezone...
-> Found 1 distinct timezone groups.
Phase 2: Clustering by category...
üéØ Initial Clustering Complete: 1 teams created, 4 members initially unassigned.
Phase 4: Reassigning 4 orphaned members...
ü§ù Orphan Reassignment Complete: 4 members placed. 0 remain unassigned.
==================================================
‚úÖ TEAM FORMATION PROCESS COMPLETE
==================================================
Could not find role 'Team 2' to deprovision.
Successfully deleted team 'Team 2' and its resources.
Database manager initialized.
logging in using static token
[31m[1mWARNING: This is a development server. Do not use it in a production deployment. Use a production WSGI server instead.[0m
 * Running on all addresses (0.0.0.0)
 * Running on http://127.0.0.1:8080
 * Running on http://192.168.0.5:8080
[33mPress CTRL+C to quit[0m
Shard ID None has connected to Gateway (Session ID: 7f4a984b5804dacf714275b9590f64d0).
Bot logged in as Betterment#4897
Bot ID: 1392030134373974066
TeamsCog loaded successfully.
Loaded cog: cogs.teams.cog
Connected to 1 guilds
Synced 6 global commands
==================================================
üöÄ STARTING HIERARCHICAL TEAM FORMATION
==================================================
üå± Initializing with 1 leaders and 4 members.
Phase 1: Clustering members by timezone...
-> Found 1 distinct timezone groups.
Phase 2: Clustering by category...
üéØ Initial Clustering Complete: 1 teams created, 4 members initially unassigned.
Phase 4: Reassigning 4 orphaned members...
ü§ù Orphan Reassignment Complete: 4 members placed. 0 remain unassigned.
==================================================
‚úÖ TEAM FORMATION PROCESS COMPLETE
==================================================
Database manager initialized.
logging in using static token
[31m[1mWARNING: This is a development server. Do not use it in a production deployment. Use a production WSGI server instead.[0m
 * Running on all addresses (0.0.0.0)
 * Running on http://127.0.0.1:8080
 * Running on http://192.168.0.5:8080
[33mPress CTRL+C to quit[0m
Shard ID None has connected to Gateway (Session ID: d75a0213b20591db078583a2a2b28ffc).
Bot logged in as Betterment#4897
Bot ID: 1392030134373974066
TeamsCog loaded successfully.
Loaded cog: cogs.teams.cog
Connected to 1 guilds
Synced 6 global commands
==================================================
üöÄ STARTING HIERARCHICAL TEAM FORMATION
==================================================
üå± Initializing with 1 leaders and 4 members.
Phase 1: Clustering members by timezone...
-> Found 1 distinct timezone groups.
Phase 2: Clustering by category...
üéØ Initial Clustering Complete: 1 teams created, 4 members initially unassigned.
Phase 4: Reassigning 4 orphaned members...
ü§ù Orphan Reassignment Complete: 4 members placed. 0 remain unassigned.
==================================================
‚úÖ TEAM FORMATION PROCESS COMPLETE
==================================================
==================================================
üöÄ STARTING HIERARCHICAL TEAM FORMATION
==================================================
üå± Initializing with 1 leaders and 4 members.
Phase 1: Clustering members by timezone...
-> Found 1 distinct timezone groups.
Phase 2: Clustering by category...
üéØ Initial Clustering Complete: 1 teams created, 4 members initially unassigned.
Phase 4: Reassigning 4 orphaned members...
ü§ù Orphan Reassignment Complete: 4 members placed. 0 remain unassigned.
==================================================
‚úÖ TEAM FORMATION PROCESS COMPLETE
==================================================
Database manager initialized.
logging in using static token
[31m[1mWARNING: This is a development server. Do not use it in a production deployment. Use a production WSGI server instead.[0m
 * Running on all addresses (0.0.0.0)
 * Running on http://127.0.0.1:8080
 * Running on http://192.168.0.5:8080
[33mPress CTRL+C to quit[0m
Shard ID None has connected to Gateway (Session ID: 080f7089023a4ee4ea99e3e65be27faa).
Bot logged in as Betterment#4897
Bot ID: 1392030134373974066
TeamsCog loaded successfully.
Loaded cog: cogs.teams.cog
Connected to 1 guilds
Synced 6 global commands
==================================================
üöÄ STARTING HIERARCHICAL TEAM FORMATION
==================================================
üå± Initializing with 1 leaders and 4 members.
Phase 1: Clustering members by timezone...
-> Found 1 distinct timezone groups.
Phase 2: Clustering by category...
üéØ Initial Clustering Complete: 1 teams created, 4 members initially unassigned.
Phase 4: Reassigning 4 orphaned members...
ü§ù Orphan Reassignment Complete: 4 members placed. 0 remain unassigned.
==================================================
‚úÖ TEAM FORMATION PROCESS COMPLETE
==================================================
Database manager initialized.
logging in using static token
[31m[1mWARNING: This is a development server. Do not use it in a production deployment. Use a production WSGI server instead.[0m
 * Running on all addresses (0.0.0.0)
 * Running on http://127.0.0.1:8080
 * Running on http://192.168.0.5:8080
[33mPress CTRL+C to quit[0m
Shard ID None has connected to Gateway (Session ID: 6cabc5869ca61082f4ee687a00ab54b9).
Bot logged in as Betterment#4897
Bot ID: 1392030134373974066
TeamsCog loaded successfully.
Loaded cog: cogs.teams.cog
Connected to 1 guilds
Synced 6 global commands
==================================================
üöÄ STARTING HIERARCHICAL TEAM FORMATION
==================================================
üå± Initializing with 1 leaders and 4 members.
Phase 1: Clustering members by timezone...
-> Found 1 distinct timezone groups.
Phase 2: Clustering by category...
üéØ Initial Clustering Complete: 1 teams created, 4 members initially unassigned.
Phase 4: Reassigning 4 orphaned members...
ü§ù Orphan Reassignment Complete: 4 members placed. 0 remain unassigned.
==================================================
‚úÖ TEAM FORMATION PROCESS COMPLETE
==================================================
==================================================
üöÄ STARTING HIERARCHICAL TEAM FORMATION
==================================================
üå± Initializing with 1 leaders and 4 members.
Phase 1: Clustering members by timezone...
-> Found 1 distinct timezone groups.
Phase 2: Clustering by category...
üéØ Initial Clustering Complete: 1 teams created, 4 members initially unassigned.
Phase 4: Reassigning 4 orphaned members...
ü§ù Orphan Reassignment Complete: 4 members placed. 0 remain unassigned.
==================================================
‚úÖ TEAM FORMATION PROCESS COMPLETE
==================================================
Failed to create proposed team 1: 'dict' object has no attribute 'team_role'
Traceback (most recent call last):
  File "d:\Home\Documents\Programming\Python\Developer Mode\Discord\Betterment\Bot\cogs\teams\services\team_formation_service.py", line 274, in batch_create_teams
    await provision_team_resources(guild, team)
  File "d:\Home\Documents\Programming\Python\Developer Mode\Discord\Betterment\Bot\cogs\teams\utils\team_utils.py", line 61, in provision_team_resources
    role = discord.utils.get(guild.roles, name=team.team_role) or await guild.create_role(name=team.team_role, reason=f"Provisioning for {team.team_role}")
                                               ^^^^^^^^^^^^^^
AttributeError: 'dict' object has no attribute 'team_role'
Database manager initialized.
logging in using static token
[31m[1mWARNING: This is a development server. Do not use it in a production deployment. Use a production WSGI server instead.[0m
 * Running on all addresses (0.0.0.0)
 * Running on http://127.0.0.1:8080
 * Running on http://192.168.0.5:8080
[33mPress CTRL+C to quit[0m
Shard ID None has connected to Gateway (Session ID: 27f0e836d0b09bbd317205fa59d825c5).
Bot logged in as Betterment#4897
Bot ID: 1392030134373974066
TeamsCog loaded successfully.
Loaded cog: cogs.teams.cog
Connected to 1 guilds
Synced 6 global commands
==================================================
üöÄ STARTING HIERARCHICAL TEAM FORMATION
==================================================
üå± Initializing with 1 leaders and 4 members.
Phase 1: Clustering members by timezone...
-> Found 1 distinct timezone groups.
Phase 2: Clustering by category...
üéØ Initial Clustering Complete: 1 teams created, 4 members initially unassigned.
Phase 4: Reassigning 4 orphaned members...
ü§ù Orphan Reassignment Complete: 4 members placed. 0 remain unassigned.
==================================================
‚úÖ TEAM FORMATION PROCESS COMPLETE
==================================================
Failed to create proposed team 1: 'dict' object has no attribute 'team_role'
Traceback (most recent call last):
  File "d:\Home\Documents\Programming\Python\Developer Mode\Discord\Betterment\Bot\cogs\teams\services\team_formation_service.py", line 275, in batch_create_teams
    await provision_team_resources(guild, team)
  File "d:\Home\Documents\Programming\Python\Developer Mode\Discord\Betterment\Bot\cogs\teams\utils\team_utils.py", line 62, in provision_team_resources
    role = discord.utils.get(guild.roles, name=team.team_role) or await guild.create_role(name=team.team_role, reason=f"Provisioning for {team.team_role}")
                                               ^^^^^^^^^^^^^^
AttributeError: 'dict' object has no attribute 'team_role'
Database manager initialized.
logging in using static token
[31m[1mWARNING: This is a development server. Do not use it in a production deployment. Use a production WSGI server instead.[0m
 * Running on all addresses (0.0.0.0)
 * Running on http://127.0.0.1:8080
 * Running on http://192.168.0.5:8080
[33mPress CTRL+C to quit[0m
Shard ID None has connected to Gateway (Session ID: ae31dd0b7e31b3e9819bddc0881b609b).
Bot logged in as Betterment#4897
Bot ID: 1392030134373974066
TeamsCog loaded successfully.
Loaded cog: cogs.teams.cog
Connected to 1 guilds
Synced 6 global commands
==================================================
üöÄ STARTING HIERARCHICAL TEAM FORMATION
==================================================
üå± Initializing with 1 leaders and 4 members.
Phase 1: Clustering members by timezone...
-> Found 1 distinct timezone groups.
Phase 2: Clustering by category...
üéØ Initial Clustering Complete: 1 teams created, 4 members initially unassigned.
Phase 4: Reassigning 4 orphaned members...
ü§ù Orphan Reassignment Complete: 4 members placed. 0 remain unassigned.
==================================================
‚úÖ TEAM FORMATION PROCESS COMPLETE
==================================================
Database manager initialized.
logging in using static token
[31m[1mWARNING: This is a development server. Do not use it in a production deployment. Use a production WSGI server instead.[0m
 * Running on all addresses (0.0.0.0)
 * Running on http://127.0.0.1:8080
 * Running on http://192.168.0.5:8080
[33mPress CTRL+C to quit[0m
Shard ID None has connected to Gateway (Session ID: 93ce1138aa3d8c44d80ad98191431bca).
Bot logged in as Betterment#4897
Bot ID: 1392030134373974066
TeamsCog loaded successfully.
Loaded cog: cogs.teams.cog
Connected to 1 guilds
Synced 6 global commands
Database manager initialized.
logging in using static token
[31m[1mWARNING: This is a development server. Do not use it in a production deployment. Use a production WSGI server instead.[0m
 * Running on all addresses (0.0.0.0)
 * Running on http://127.0.0.1:8080
 * Running on http://192.168.0.5:8080
[33mPress CTRL+C to quit[0m
Shard ID None has connected to Gateway (Session ID: 08a2afd7e34443d33ee3210f43428d42).
Bot logged in as Betterment#4897
Bot ID: 1392030134373974066
TeamsCog loaded successfully.
Loaded cog: cogs.teams.cog
Connected to 1 guilds
Synced 6 global commands
Command error in GumBall: Command "help" is not found
Database manager initialized.
logging in using static token
[31m[1mWARNING: This is a development server. Do not use it in a production deployment. Use a production WSGI server instead.[0m
 * Running on all addresses (0.0.0.0)
 * Running on http://127.0.0.1:8080
 * Running on http://192.168.0.5:8080
[33mPress CTRL+C to quit[0m
Shard ID None has connected to Gateway (Session ID: 164be5a6ccd9f723c08c534df41cb839).
Bot logged in as Betterment#4897
Bot ID: 1392030134373974066
TeamsCog loaded successfully.
Loaded cog: cogs.teams.cog
Connected to 1 guilds
Synced 6 global commands
Error in profile parsing: 'TeamManager' object has no attribute '_get_member_role_title'
Traceback (most recent call last):
  File "d:\Home\Documents\Programming\Python\Developer Mode\Discord\Betterment\Bot\cogs\teams\profile_parsing.py", line 25, in handle_profile_parsing
    role_title = self.team_manager._get_member_role_title(message.author)
                 ^^^^^^^^^^^^^^^^^^^^^^^^^^^^^^^^^^^^^^^^
AttributeError: 'TeamManager' object has no attribute '_get_member_role_title'
Database manager initialized.
logging in using static token
[31m[1mWARNING: This is a development server. Do not use it in a production deployment. Use a production WSGI server instead.[0m
 * Running on all addresses (0.0.0.0)
 * Running on http://127.0.0.1:8080
 * Running on http://192.168.0.5:8080
[33mPress CTRL+C to quit[0m
Shard ID None has connected to Gateway (Session ID: 81e5851ee9ece9be0436cb7b2c057460).
Bot logged in as Betterment#4897
Bot ID: 1392030134373974066
Database manager initialized.
logging in using static token
[31m[1mWARNING: This is a development server. Do not use it in a production deployment. Use a production WSGI server instead.[0m
 * Running on all addresses (0.0.0.0)
 * Running on http://127.0.0.1:8080
 * Running on http://192.168.0.5:8080
[33mPress CTRL+C to quit[0m
Shard ID None has connected to Gateway (Session ID: 7edf057934098cbc7dcde5cebb7c264c).
Bot logged in as Betterment#4897
Bot ID: 1392030134373974066
TeamsCog loaded successfully.
Loaded cog: cogs.teams.cog
Connected to 1 guilds
Synced 6 global commands
Database manager initialized.
logging in using static token
[31m[1mWARNING: This is a development server. Do not use it in a production deployment. Use a production WSGI server instead.[0m
 * Running on all addresses (0.0.0.0)
 * Running on http://127.0.0.1:8080
 * Running on http://192.168.0.5:8080
[33mPress CTRL+C to quit[0m
Shard ID None has connected to Gateway (Session ID: 2cb07a515c94e9e8538773e2a82d6d02).
Bot logged in as Betterment#4897
Bot ID: 1392030134373974066
TeamsCog loaded successfully.
Loaded cog: cogs.teams.cog
Connected to 1 guilds
Synced 6 global commands
Successfully updated channel name for team 'Team 1' to 'testing'.
Could not find role 'Team 2' to deprovision.
An unhandled command error occurred in TeamsCog: Command 'create_team' raised an exception: InvalidDocument: Invalid document {'guild_id': 1375913075491737670, 'team_role': 'Team 2', 'channel_name': 'bruh', 'members': {'1071467618420150414': TeamMember(user_id='1071467618420150414', username='neural_network', display_name='neuron', role_title='Team Member', profile_data={})}, '_team_number': 2, 'created_at': datetime.datetime(2025, 8, 21, 14, 26, 57, 690904), 'updated_at': datetime.datetime(2025, 8, 21, 14, 26, 57, 690908), '_id': ObjectId('68a72cb1727fbc5090d5d680')} | cannot encode object: TeamMember(user_id='1071467618420150414', username='neural_network', display_name='neuron', role_title='Team Member', profile_data={}), of type: <class 'cogs.teams.models.team.TeamMember'>
Traceback (most recent call last):
  File "C:\Users\Joseph\AppData\Local\Programs\Python\Python313\Lib\site-packages\discord\app_commands\commands.py", line 857, in _do_call
    return await self._callback(self.binding, interaction, **params)  # type: ignore
           ^^^^^^^^^^^^^^^^^^^^^^^^^^^^^^^^^^^^^^^^^^^^^^^^^^^^^^^^^
  File "d:\Home\Documents\Programming\Python\Developer Mode\Discord\Betterment\Bot\cogs\teams\permissions.py", line 66, in wrapper
    return await func(*args, **kwargs)
           ^^^^^^^^^^^^^^^^^^^^^^^^^^^
  File "d:\Home\Documents\Programming\Python\Developer Mode\Discord\Betterment\Bot\cogs\teams\cog.py", line 113, in create_team
    team = await self.team_manager.create_team(interaction.guild, team_number, channel_name, members)
           ^^^^^^^^^^^^^^^^^^^^^^^^^^^^^^^^^^^^^^^^^^^^^^^^^^^^^^^^^^^^^^^^^^^^^^^^^^^^^^^^^^^^^^^^^^
  File "d:\Home\Documents\Programming\Python\Developer Mode\Discord\Betterment\Bot\cogs\teams\services\team_manager.py", line 39, in create_team
    return await self.team_service.create_team(*args, **kwargs)
           ^^^^^^^^^^^^^^^^^^^^^^^^^^^^^^^^^^^^^^^^^^^^^^^^^^^^
  File "d:\Home\Documents\Programming\Python\Developer Mode\Discord\Betterment\Bot\cogs\teams\services\team_service.py", line 44, in create_team
    await self.db.insert_team(vars(team))
  File "d:\Home\Documents\Programming\Python\Developer Mode\Discord\Betterment\Bot\database.py", line 66, in insert_team
    return await self.teams.insert_one(team_data)
           ^^^^^^^^^^^^^^^^^^^^^^^^^^^^^^^^^^^^^^
  File "C:\Users\Joseph\AppData\Local\Programs\Python\Python313\Lib\concurrent\futures\thread.py", line 59, in run
    result = self.fn(*self.args, **self.kwargs)
  File "C:\Users\Joseph\AppData\Local\Programs\Python\Python313\Lib\site-packages\pymongo\synchronous\collection.py", line 891, in insert_one
    self._insert_one(
    ~~~~~~~~~~~~~~~~^
        document,
        ^^^^^^^^^
    ...<5 lines>...
        comment=comment,
        ^^^^^^^^^^^^^^^^
    ),
    ^
  File "C:\Users\Joseph\AppData\Local\Programs\Python\Python313\Lib\site-packages\pymongo\synchronous\collection.py", line 831, in _insert_one
    self._database.client._retryable_write(
    ~~~~~~~~~~~~~~~~~~~~~~~~~~~~~~~~~~~~~~^
        acknowledged, _insert_command, session, operation=_Op.INSERT
        ^^^^^^^^^^^^^^^^^^^^^^^^^^^^^^^^^^^^^^^^^^^^^^^^^^^^^^^^^^^^
    )
    ^
  File "C:\Users\Joseph\AppData\Local\Programs\Python\Python313\Lib\site-packages\pymongo\synchronous\mongo_client.py", line 2061, in _retryable_write
    return self._retry_with_session(retryable, func, s, bulk, operation, operation_id)
           ~~~~~~~~~~~~~~~~~~~~~~~~^^^^^^^^^^^^^^^^^^^^^^^^^^^^^^^^^^^^^^^^^^^^^^^^^^^
  File "C:\Users\Joseph\AppData\Local\Programs\Python\Python313\Lib\site-packages\pymongo\synchronous\mongo_client.py", line 1947, in _retry_with_session
    return self._retry_internal(
           ~~~~~~~~~~~~~~~~~~~~^
        func=func,
        ^^^^^^^^^^
    ...<4 lines>...
        operation_id=operation_id,
        ^^^^^^^^^^^^^^^^^^^^^^^^^^
    )
    ^
  File "C:\Users\Joseph\AppData\Local\Programs\Python\Python313\Lib\site-packages\pymongo\_csot.py", line 125, in csot_wrapper
    return func(self, *args, **kwargs)
  File "C:\Users\Joseph\AppData\Local\Programs\Python\Python313\Lib\site-packages\pymongo\synchronous\mongo_client.py", line 1993, in _retry_internal
    ).run()
      ~~~^^
  File "C:\Users\Joseph\AppData\Local\Programs\Python\Python313\Lib\site-packages\pymongo\synchronous\mongo_client.py", line 2730, in run
    return self._read() if self._is_read else self._write()
                                              ~~~~~~~~~~~^^
  File "C:\Users\Joseph\AppData\Local\Programs\Python\Python313\Lib\site-packages\pymongo\synchronous\mongo_client.py", line 2862, in _write
    return self._func(self._session, conn, self._retryable)  # type: ignore
           ~~~~~~~~~~^^^^^^^^^^^^^^^^^^^^^^^^^^^^^^^^^^^^^^
  File "C:\Users\Joseph\AppData\Local\Programs\Python\Python313\Lib\site-packages\pymongo\synchronous\collection.py", line 819, in _insert_command
    result = conn.command(
        self._database.name,
    ...<5 lines>...
        retryable_write=retryable_write,
    )
  File "C:\Users\Joseph\AppData\Local\Programs\Python\Python313\Lib\site-packages\pymongo\synchronous\helpers.py", line 47, in inner
    return func(*args, **kwargs)
  File "C:\Users\Joseph\AppData\Local\Programs\Python\Python313\Lib\site-packages\pymongo\synchronous\pool.py", line 442, in command
    self._raise_connection_failure(error)
    ~~~~~~~~~~~~~~~~~~~~~~~~~~~~~~^^^^^^^
  File "C:\Users\Joseph\AppData\Local\Programs\Python\Python313\Lib\site-packages\pymongo\synchronous\pool.py", line 414, in command
    return command(
        self,
    ...<20 lines>...
        write_concern=write_concern,
    )
  File "C:\Users\Joseph\AppData\Local\Programs\Python\Python313\Lib\site-packages\pymongo\synchronous\network.py", line 148, in command
    request_id, msg, size, max_doc_size = message._op_msg(
                                          ~~~~~~~~~~~~~~~^
        flags, spec, dbname, read_preference, codec_options, ctx=compression_ctx
        ^^^^^^^^^^^^^^^^^^^^^^^^^^^^^^^^^^^^^^^^^^^^^^^^^^^^^^^^^^^^^^^^^^^^^^^^
    )
    ^
  File "C:\Users\Joseph\AppData\Local\Programs\Python\Python313\Lib\site-packages\pymongo\message.py", line 419, in _op_msg
    return _op_msg_uncompressed(flags, command, identifier, docs, opts)
bson.errors.InvalidDocument: Invalid document {'guild_id': 1375913075491737670, 'team_role': 'Team 2', 'channel_name': 'bruh', 'members': {'1071467618420150414': TeamMember(user_id='1071467618420150414', username='neural_network', display_name='neuron', role_title='Team Member', profile_data={})}, '_team_number': 2, 'created_at': datetime.datetime(2025, 8, 21, 14, 26, 57, 690904), 'updated_at': datetime.datetime(2025, 8, 21, 14, 26, 57, 690908), '_id': ObjectId('68a72cb1727fbc5090d5d680')} | cannot encode object: TeamMember(user_id='1071467618420150414', username='neural_network', display_name='neuron', role_title='Team Member', profile_data={}), of type: <class 'cogs.teams.models.team.TeamMember'>

The above exception was the direct cause of the following exception:

Traceback (most recent call last):
  File "C:\Users\Joseph\AppData\Local\Programs\Python\Python313\Lib\site-packages\discord\app_commands\tree.py", line 1310, in _call
    await command._invoke_with_namespace(interaction, namespace)
  File "C:\Users\Joseph\AppData\Local\Programs\Python\Python313\Lib\site-packages\discord\app_commands\commands.py", line 883, in _invoke_with_namespace
    return await self._do_call(interaction, transformed_values)
           ^^^^^^^^^^^^^^^^^^^^^^^^^^^^^^^^^^^^^^^^^^^^^^^^^^^^
  File "C:\Users\Joseph\AppData\Local\Programs\Python\Python313\Lib\site-packages\discord\app_commands\commands.py", line 876, in _do_call
    raise CommandInvokeError(self, e) from e
discord.app_commands.errors.CommandInvokeError: Command 'create_team' raised an exception: InvalidDocument: Invalid document {'guild_id': 1375913075491737670, 'team_role': 'Team 2', 'channel_name': 'bruh', 'members': {'1071467618420150414': TeamMember(user_id='1071467618420150414', username='neural_network', display_name='neuron', role_title='Team Member', profile_data={})}, '_team_number': 2, 'created_at': datetime.datetime(2025, 8, 21, 14, 26, 57, 690904), 'updated_at': datetime.datetime(2025, 8, 21, 14, 26, 57, 690908), '_id': ObjectId('68a72cb1727fbc5090d5d680')} | cannot encode object: TeamMember(user_id='1071467618420150414', username='neural_network', display_name='neuron', role_title='Team Member', profile_data={}), of type: <class 'cogs.teams.models.team.TeamMember'>
An unhandled command error occurred in TeamsCog: Command 'create_team' raised an exception: InvalidDocument: Invalid document {'guild_id': 1375913075491737670, 'team_role': 'Team 2', 'channel_name': 'bruh', 'members': {'1071467618420150414': TeamMember(user_id='1071467618420150414', username='neural_network', display_name='neuron', role_title='Team Member', profile_data={})}, '_team_number': 2, 'created_at': datetime.datetime(2025, 8, 21, 14, 27, 48, 772391), 'updated_at': datetime.datetime(2025, 8, 21, 14, 27, 48, 772395), '_id': ObjectId('68a72ce4727fbc5090d5d681')} | cannot encode object: TeamMember(user_id='1071467618420150414', username='neural_network', display_name='neuron', role_title='Team Member', profile_data={}), of type: <class 'cogs.teams.models.team.TeamMember'>
Traceback (most recent call last):
  File "C:\Users\Joseph\AppData\Local\Programs\Python\Python313\Lib\site-packages\discord\app_commands\commands.py", line 857, in _do_call
    return await self._callback(self.binding, interaction, **params)  # type: ignore
           ^^^^^^^^^^^^^^^^^^^^^^^^^^^^^^^^^^^^^^^^^^^^^^^^^^^^^^^^^
  File "d:\Home\Documents\Programming\Python\Developer Mode\Discord\Betterment\Bot\cogs\teams\permissions.py", line 66, in wrapper
    return await func(*args, **kwargs)
           ^^^^^^^^^^^^^^^^^^^^^^^^^^^
  File "d:\Home\Documents\Programming\Python\Developer Mode\Discord\Betterment\Bot\cogs\teams\cog.py", line 113, in create_team
    team = await self.team_manager.create_team(interaction.guild, team_number, channel_name, members)
           ^^^^^^^^^^^^^^^^^^^^^^^^^^^^^^^^^^^^^^^^^^^^^^^^^^^^^^^^^^^^^^^^^^^^^^^^^^^^^^^^^^^^^^^^^^
  File "d:\Home\Documents\Programming\Python\Developer Mode\Discord\Betterment\Bot\cogs\teams\services\team_manager.py", line 39, in create_team
    return await self.team_service.create_team(*args, **kwargs)
           ^^^^^^^^^^^^^^^^^^^^^^^^^^^^^^^^^^^^^^^^^^^^^^^^^^^^
  File "d:\Home\Documents\Programming\Python\Developer Mode\Discord\Betterment\Bot\cogs\teams\services\team_service.py", line 44, in create_team
    await self.db.insert_team(vars(team))
  File "d:\Home\Documents\Programming\Python\Developer Mode\Discord\Betterment\Bot\database.py", line 66, in insert_team
    return await self.teams.insert_one(team_data)
           ^^^^^^^^^^^^^^^^^^^^^^^^^^^^^^^^^^^^^^
  File "C:\Users\Joseph\AppData\Local\Programs\Python\Python313\Lib\concurrent\futures\thread.py", line 59, in run
    result = self.fn(*self.args, **self.kwargs)
  File "C:\Users\Joseph\AppData\Local\Programs\Python\Python313\Lib\site-packages\pymongo\synchronous\collection.py", line 891, in insert_one
    self._insert_one(
    ~~~~~~~~~~~~~~~~^
        document,
        ^^^^^^^^^
    ...<5 lines>...
        comment=comment,
        ^^^^^^^^^^^^^^^^
    ),
    ^
  File "C:\Users\Joseph\AppData\Local\Programs\Python\Python313\Lib\site-packages\pymongo\synchronous\collection.py", line 831, in _insert_one
    self._database.client._retryable_write(
    ~~~~~~~~~~~~~~~~~~~~~~~~~~~~~~~~~~~~~~^
        acknowledged, _insert_command, session, operation=_Op.INSERT
        ^^^^^^^^^^^^^^^^^^^^^^^^^^^^^^^^^^^^^^^^^^^^^^^^^^^^^^^^^^^^
    )
    ^
  File "C:\Users\Joseph\AppData\Local\Programs\Python\Python313\Lib\site-packages\pymongo\synchronous\mongo_client.py", line 2061, in _retryable_write
    return self._retry_with_session(retryable, func, s, bulk, operation, operation_id)
           ~~~~~~~~~~~~~~~~~~~~~~~~^^^^^^^^^^^^^^^^^^^^^^^^^^^^^^^^^^^^^^^^^^^^^^^^^^^
  File "C:\Users\Joseph\AppData\Local\Programs\Python\Python313\Lib\site-packages\pymongo\synchronous\mongo_client.py", line 1947, in _retry_with_session
    return self._retry_internal(
           ~~~~~~~~~~~~~~~~~~~~^
        func=func,
        ^^^^^^^^^^
    ...<4 lines>...
        operation_id=operation_id,
        ^^^^^^^^^^^^^^^^^^^^^^^^^^
    )
    ^
  File "C:\Users\Joseph\AppData\Local\Programs\Python\Python313\Lib\site-packages\pymongo\_csot.py", line 125, in csot_wrapper
    return func(self, *args, **kwargs)
  File "C:\Users\Joseph\AppData\Local\Programs\Python\Python313\Lib\site-packages\pymongo\synchronous\mongo_client.py", line 1993, in _retry_internal
    ).run()
      ~~~^^
  File "C:\Users\Joseph\AppData\Local\Programs\Python\Python313\Lib\site-packages\pymongo\synchronous\mongo_client.py", line 2730, in run
    return self._read() if self._is_read else self._write()
                                              ~~~~~~~~~~~^^
  File "C:\Users\Joseph\AppData\Local\Programs\Python\Python313\Lib\site-packages\pymongo\synchronous\mongo_client.py", line 2862, in _write
    return self._func(self._session, conn, self._retryable)  # type: ignore
           ~~~~~~~~~~^^^^^^^^^^^^^^^^^^^^^^^^^^^^^^^^^^^^^^
  File "C:\Users\Joseph\AppData\Local\Programs\Python\Python313\Lib\site-packages\pymongo\synchronous\collection.py", line 819, in _insert_command
    result = conn.command(
        self._database.name,
    ...<5 lines>...
        retryable_write=retryable_write,
    )
  File "C:\Users\Joseph\AppData\Local\Programs\Python\Python313\Lib\site-packages\pymongo\synchronous\helpers.py", line 47, in inner
    return func(*args, **kwargs)
  File "C:\Users\Joseph\AppData\Local\Programs\Python\Python313\Lib\site-packages\pymongo\synchronous\pool.py", line 442, in command
    self._raise_connection_failure(error)
    ~~~~~~~~~~~~~~~~~~~~~~~~~~~~~~^^^^^^^
  File "C:\Users\Joseph\AppData\Local\Programs\Python\Python313\Lib\site-packages\pymongo\synchronous\pool.py", line 414, in command
    return command(
        self,
    ...<20 lines>...
        write_concern=write_concern,
    )
  File "C:\Users\Joseph\AppData\Local\Programs\Python\Python313\Lib\site-packages\pymongo\synchronous\network.py", line 148, in command
    request_id, msg, size, max_doc_size = message._op_msg(
                                          ~~~~~~~~~~~~~~~^
        flags, spec, dbname, read_preference, codec_options, ctx=compression_ctx
        ^^^^^^^^^^^^^^^^^^^^^^^^^^^^^^^^^^^^^^^^^^^^^^^^^^^^^^^^^^^^^^^^^^^^^^^^
    )
    ^
  File "C:\Users\Joseph\AppData\Local\Programs\Python\Python313\Lib\site-packages\pymongo\message.py", line 419, in _op_msg
    return _op_msg_uncompressed(flags, command, identifier, docs, opts)
bson.errors.InvalidDocument: Invalid document {'guild_id': 1375913075491737670, 'team_role': 'Team 2', 'channel_name': 'bruh', 'members': {'1071467618420150414': TeamMember(user_id='1071467618420150414', username='neural_network', display_name='neuron', role_title='Team Member', profile_data={})}, '_team_number': 2, 'created_at': datetime.datetime(2025, 8, 21, 14, 27, 48, 772391), 'updated_at': datetime.datetime(2025, 8, 21, 14, 27, 48, 772395), '_id': ObjectId('68a72ce4727fbc5090d5d681')} | cannot encode object: TeamMember(user_id='1071467618420150414', username='neural_network', display_name='neuron', role_title='Team Member', profile_data={}), of type: <class 'cogs.teams.models.team.TeamMember'>

The above exception was the direct cause of the following exception:

Traceback (most recent call last):
  File "C:\Users\Joseph\AppData\Local\Programs\Python\Python313\Lib\site-packages\discord\app_commands\tree.py", line 1310, in _call
    await command._invoke_with_namespace(interaction, namespace)
  File "C:\Users\Joseph\AppData\Local\Programs\Python\Python313\Lib\site-packages\discord\app_commands\commands.py", line 883, in _invoke_with_namespace
    return await self._do_call(interaction, transformed_values)
           ^^^^^^^^^^^^^^^^^^^^^^^^^^^^^^^^^^^^^^^^^^^^^^^^^^^^
  File "C:\Users\Joseph\AppData\Local\Programs\Python\Python313\Lib\site-packages\discord\app_commands\commands.py", line 876, in _do_call
    raise CommandInvokeError(self, e) from e
discord.app_commands.errors.CommandInvokeError: Command 'create_team' raised an exception: InvalidDocument: Invalid document {'guild_id': 1375913075491737670, 'team_role': 'Team 2', 'channel_name': 'bruh', 'members': {'1071467618420150414': TeamMember(user_id='1071467618420150414', username='neural_network', display_name='neuron', role_title='Team Member', profile_data={})}, '_team_number': 2, 'created_at': datetime.datetime(2025, 8, 21, 14, 27, 48, 772391), 'updated_at': datetime.datetime(2025, 8, 21, 14, 27, 48, 772395), '_id': ObjectId('68a72ce4727fbc5090d5d681')} | cannot encode object: TeamMember(user_id='1071467618420150414', username='neural_network', display_name='neuron', role_title='Team Member', profile_data={}), of type: <class 'cogs.teams.models.team.TeamMember'>
Database manager initialized.
logging in using static token
[31m[1mWARNING: This is a development server. Do not use it in a production deployment. Use a production WSGI server instead.[0m
 * Running on all addresses (0.0.0.0)
 * Running on http://127.0.0.1:8080
 * Running on http://192.168.0.5:8080
[33mPress CTRL+C to quit[0m
Shard ID None has connected to Gateway (Session ID: eb80d8fab788296e999f9597c11ed565).
Bot logged in as Betterment#4897
Bot ID: 1392030134373974066
TeamsCog loaded successfully.
Loaded cog: cogs.teams.cog
Connected to 1 guilds
Synced 6 global commands
An unhandled command error occurred in TeamsCog: Command 'create_team' raised an exception: InvalidDocument: Invalid document {'guild_id': 1375913075491737670, 'team_role': 'Team 2', 'channel_name': 'bruh', 'members': {'1071467618420150414': TeamMember(user_id='1071467618420150414', username='neural_network', display_name='neuron', role_title='Team Member', profile_data={})}, '_team_number': 2, 'created_at': datetime.datetime(2025, 8, 21, 14, 29, 10, 373762), 'updated_at': datetime.datetime(2025, 8, 21, 14, 29, 10, 373767), '_id': ObjectId('68a72d36ebff43c25169e35b')} | cannot encode object: TeamMember(user_id='1071467618420150414', username='neural_network', display_name='neuron', role_title='Team Member', profile_data={}), of type: <class 'cogs.teams.models.team.TeamMember'>
Traceback (most recent call last):
  File "C:\Users\Joseph\AppData\Local\Programs\Python\Python313\Lib\site-packages\discord\app_commands\commands.py", line 857, in _do_call
    return await self._callback(self.binding, interaction, **params)  # type: ignore
           ^^^^^^^^^^^^^^^^^^^^^^^^^^^^^^^^^^^^^^^^^^^^^^^^^^^^^^^^^
  File "d:\Home\Documents\Programming\Python\Developer Mode\Discord\Betterment\Bot\cogs\teams\permissions.py", line 66, in wrapper
    return await func(*args, **kwargs)
           ^^^^^^^^^^^^^^^^^^^^^^^^^^^
  File "d:\Home\Documents\Programming\Python\Developer Mode\Discord\Betterment\Bot\cogs\teams\cog.py", line 113, in create_team
    team = await self.team_manager.create_team(interaction.guild, team_number, channel_name, members)
           ^^^^^^^^^^^^^^^^^^^^^^^^^^^^^^^^^^^^^^^^^^^^^^^^^^^^^^^^^^^^^^^^^^^^^^^^^^^^^^^^^^^^^^^^^^
  File "d:\Home\Documents\Programming\Python\Developer Mode\Discord\Betterment\Bot\cogs\teams\services\team_manager.py", line 39, in create_team
    return await self.team_service.create_team(*args, **kwargs)
           ^^^^^^^^^^^^^^^^^^^^^^^^^^^^^^^^^^^^^^^^^^^^^^^^^^^^
  File "d:\Home\Documents\Programming\Python\Developer Mode\Discord\Betterment\Bot\cogs\teams\services\team_service.py", line 44, in create_team
    await self.db.insert_team(vars(team))
  File "d:\Home\Documents\Programming\Python\Developer Mode\Discord\Betterment\Bot\database.py", line 66, in insert_team
    return await self.teams.insert_one(team_data)
           ^^^^^^^^^^^^^^^^^^^^^^^^^^^^^^^^^^^^^^
  File "C:\Users\Joseph\AppData\Local\Programs\Python\Python313\Lib\concurrent\futures\thread.py", line 59, in run
    result = self.fn(*self.args, **self.kwargs)
  File "C:\Users\Joseph\AppData\Local\Programs\Python\Python313\Lib\site-packages\pymongo\synchronous\collection.py", line 891, in insert_one
    self._insert_one(
    ~~~~~~~~~~~~~~~~^
        document,
        ^^^^^^^^^
    ...<5 lines>...
        comment=comment,
        ^^^^^^^^^^^^^^^^
    ),
    ^
  File "C:\Users\Joseph\AppData\Local\Programs\Python\Python313\Lib\site-packages\pymongo\synchronous\collection.py", line 831, in _insert_one
    self._database.client._retryable_write(
    ~~~~~~~~~~~~~~~~~~~~~~~~~~~~~~~~~~~~~~^
        acknowledged, _insert_command, session, operation=_Op.INSERT
        ^^^^^^^^^^^^^^^^^^^^^^^^^^^^^^^^^^^^^^^^^^^^^^^^^^^^^^^^^^^^
    )
    ^
  File "C:\Users\Joseph\AppData\Local\Programs\Python\Python313\Lib\site-packages\pymongo\synchronous\mongo_client.py", line 2061, in _retryable_write
    return self._retry_with_session(retryable, func, s, bulk, operation, operation_id)
           ~~~~~~~~~~~~~~~~~~~~~~~~^^^^^^^^^^^^^^^^^^^^^^^^^^^^^^^^^^^^^^^^^^^^^^^^^^^
  File "C:\Users\Joseph\AppData\Local\Programs\Python\Python313\Lib\site-packages\pymongo\synchronous\mongo_client.py", line 1947, in _retry_with_session
    return self._retry_internal(
           ~~~~~~~~~~~~~~~~~~~~^
        func=func,
        ^^^^^^^^^^
    ...<4 lines>...
        operation_id=operation_id,
        ^^^^^^^^^^^^^^^^^^^^^^^^^^
    )
    ^
  File "C:\Users\Joseph\AppData\Local\Programs\Python\Python313\Lib\site-packages\pymongo\_csot.py", line 125, in csot_wrapper
    return func(self, *args, **kwargs)
  File "C:\Users\Joseph\AppData\Local\Programs\Python\Python313\Lib\site-packages\pymongo\synchronous\mongo_client.py", line 1993, in _retry_internal
    ).run()
      ~~~^^
  File "C:\Users\Joseph\AppData\Local\Programs\Python\Python313\Lib\site-packages\pymongo\synchronous\mongo_client.py", line 2730, in run
    return self._read() if self._is_read else self._write()
                                              ~~~~~~~~~~~^^
  File "C:\Users\Joseph\AppData\Local\Programs\Python\Python313\Lib\site-packages\pymongo\synchronous\mongo_client.py", line 2862, in _write
    return self._func(self._session, conn, self._retryable)  # type: ignore
           ~~~~~~~~~~^^^^^^^^^^^^^^^^^^^^^^^^^^^^^^^^^^^^^^
  File "C:\Users\Joseph\AppData\Local\Programs\Python\Python313\Lib\site-packages\pymongo\synchronous\collection.py", line 819, in _insert_command
    result = conn.command(
        self._database.name,
    ...<5 lines>...
        retryable_write=retryable_write,
    )
  File "C:\Users\Joseph\AppData\Local\Programs\Python\Python313\Lib\site-packages\pymongo\synchronous\helpers.py", line 47, in inner
    return func(*args, **kwargs)
  File "C:\Users\Joseph\AppData\Local\Programs\Python\Python313\Lib\site-packages\pymongo\synchronous\pool.py", line 442, in command
    self._raise_connection_failure(error)
    ~~~~~~~~~~~~~~~~~~~~~~~~~~~~~~^^^^^^^
  File "C:\Users\Joseph\AppData\Local\Programs\Python\Python313\Lib\site-packages\pymongo\synchronous\pool.py", line 414, in command
    return command(
        self,
    ...<20 lines>...
        write_concern=write_concern,
    )
  File "C:\Users\Joseph\AppData\Local\Programs\Python\Python313\Lib\site-packages\pymongo\synchronous\network.py", line 148, in command
    request_id, msg, size, max_doc_size = message._op_msg(
                                          ~~~~~~~~~~~~~~~^
        flags, spec, dbname, read_preference, codec_options, ctx=compression_ctx
        ^^^^^^^^^^^^^^^^^^^^^^^^^^^^^^^^^^^^^^^^^^^^^^^^^^^^^^^^^^^^^^^^^^^^^^^^
    )
    ^
  File "C:\Users\Joseph\AppData\Local\Programs\Python\Python313\Lib\site-packages\pymongo\message.py", line 419, in _op_msg
    return _op_msg_uncompressed(flags, command, identifier, docs, opts)
bson.errors.InvalidDocument: Invalid document {'guild_id': 1375913075491737670, 'team_role': 'Team 2', 'channel_name': 'bruh', 'members': {'1071467618420150414': TeamMember(user_id='1071467618420150414', username='neural_network', display_name='neuron', role_title='Team Member', profile_data={})}, '_team_number': 2, 'created_at': datetime.datetime(2025, 8, 21, 14, 29, 10, 373762), 'updated_at': datetime.datetime(2025, 8, 21, 14, 29, 10, 373767), '_id': ObjectId('68a72d36ebff43c25169e35b')} | cannot encode object: TeamMember(user_id='1071467618420150414', username='neural_network', display_name='neuron', role_title='Team Member', profile_data={}), of type: <class 'cogs.teams.models.team.TeamMember'>

The above exception was the direct cause of the following exception:

Traceback (most recent call last):
  File "C:\Users\Joseph\AppData\Local\Programs\Python\Python313\Lib\site-packages\discord\app_commands\tree.py", line 1310, in _call
    await command._invoke_with_namespace(interaction, namespace)
  File "C:\Users\Joseph\AppData\Local\Programs\Python\Python313\Lib\site-packages\discord\app_commands\commands.py", line 883, in _invoke_with_namespace
    return await self._do_call(interaction, transformed_values)
           ^^^^^^^^^^^^^^^^^^^^^^^^^^^^^^^^^^^^^^^^^^^^^^^^^^^^
  File "C:\Users\Joseph\AppData\Local\Programs\Python\Python313\Lib\site-packages\discord\app_commands\commands.py", line 876, in _do_call
    raise CommandInvokeError(self, e) from e
discord.app_commands.errors.CommandInvokeError: Command 'create_team' raised an exception: InvalidDocument: Invalid document {'guild_id': 1375913075491737670, 'team_role': 'Team 2', 'channel_name': 'bruh', 'members': {'1071467618420150414': TeamMember(user_id='1071467618420150414', username='neural_network', display_name='neuron', role_title='Team Member', profile_data={})}, '_team_number': 2, 'created_at': datetime.datetime(2025, 8, 21, 14, 29, 10, 373762), 'updated_at': datetime.datetime(2025, 8, 21, 14, 29, 10, 373767), '_id': ObjectId('68a72d36ebff43c25169e35b')} | cannot encode object: TeamMember(user_id='1071467618420150414', username='neural_network', display_name='neuron', role_title='Team Member', profile_data={}), of type: <class 'cogs.teams.models.team.TeamMember'>
An unhandled command error occurred in TeamsCog: Command 'create_team' raised an exception: InvalidDocument: Invalid document {'guild_id': 1375913075491737670, 'team_role': 'Team 2', 'channel_name': 'test', 'members': {'1071467618420150414': TeamMember(user_id='1071467618420150414', username='neural_network', display_name='neuron', role_title='Team Member', profile_data={})}, '_team_number': 2, 'created_at': datetime.datetime(2025, 8, 21, 14, 31, 6, 164874), 'updated_at': datetime.datetime(2025, 8, 21, 14, 31, 6, 164878), '_id': ObjectId('68a72daaebff43c25169e35c')} | cannot encode object: TeamMember(user_id='1071467618420150414', username='neural_network', display_name='neuron', role_title='Team Member', profile_data={}), of type: <class 'cogs.teams.models.team.TeamMember'>
Traceback (most recent call last):
  File "C:\Users\Joseph\AppData\Local\Programs\Python\Python313\Lib\site-packages\discord\app_commands\commands.py", line 857, in _do_call
    return await self._callback(self.binding, interaction, **params)  # type: ignore
           ^^^^^^^^^^^^^^^^^^^^^^^^^^^^^^^^^^^^^^^^^^^^^^^^^^^^^^^^^
  File "d:\Home\Documents\Programming\Python\Developer Mode\Discord\Betterment\Bot\cogs\teams\permissions.py", line 66, in wrapper
    return await func(*args, **kwargs)
           ^^^^^^^^^^^^^^^^^^^^^^^^^^^
  File "d:\Home\Documents\Programming\Python\Developer Mode\Discord\Betterment\Bot\cogs\teams\cog.py", line 113, in create_team
    team = await self.team_manager.create_team(interaction.guild, team_number, channel_name, members)
           ^^^^^^^^^^^^^^^^^^^^^^^^^^^^^^^^^^^^^^^^^^^^^^^^^^^^^^^^^^^^^^^^^^^^^^^^^^^^^^^^^^^^^^^^^^
  File "d:\Home\Documents\Programming\Python\Developer Mode\Discord\Betterment\Bot\cogs\teams\services\team_manager.py", line 39, in create_team
    return await self.team_service.create_team(*args, **kwargs)
           ^^^^^^^^^^^^^^^^^^^^^^^^^^^^^^^^^^^^^^^^^^^^^^^^^^^^
  File "d:\Home\Documents\Programming\Python\Developer Mode\Discord\Betterment\Bot\cogs\teams\services\team_service.py", line 44, in create_team
    await self.db.insert_team(vars(team))
  File "d:\Home\Documents\Programming\Python\Developer Mode\Discord\Betterment\Bot\database.py", line 66, in insert_team
    return await self.teams.insert_one(team_data)
           ^^^^^^^^^^^^^^^^^^^^^^^^^^^^^^^^^^^^^^
  File "C:\Users\Joseph\AppData\Local\Programs\Python\Python313\Lib\concurrent\futures\thread.py", line 59, in run
    result = self.fn(*self.args, **self.kwargs)
  File "C:\Users\Joseph\AppData\Local\Programs\Python\Python313\Lib\site-packages\pymongo\synchronous\collection.py", line 891, in insert_one
    self._insert_one(
    ~~~~~~~~~~~~~~~~^
        document,
        ^^^^^^^^^
    ...<5 lines>...
        comment=comment,
        ^^^^^^^^^^^^^^^^
    ),
    ^
  File "C:\Users\Joseph\AppData\Local\Programs\Python\Python313\Lib\site-packages\pymongo\synchronous\collection.py", line 831, in _insert_one
    self._database.client._retryable_write(
    ~~~~~~~~~~~~~~~~~~~~~~~~~~~~~~~~~~~~~~^
        acknowledged, _insert_command, session, operation=_Op.INSERT
        ^^^^^^^^^^^^^^^^^^^^^^^^^^^^^^^^^^^^^^^^^^^^^^^^^^^^^^^^^^^^
    )
    ^
  File "C:\Users\Joseph\AppData\Local\Programs\Python\Python313\Lib\site-packages\pymongo\synchronous\mongo_client.py", line 2061, in _retryable_write
    return self._retry_with_session(retryable, func, s, bulk, operation, operation_id)
           ~~~~~~~~~~~~~~~~~~~~~~~~^^^^^^^^^^^^^^^^^^^^^^^^^^^^^^^^^^^^^^^^^^^^^^^^^^^
  File "C:\Users\Joseph\AppData\Local\Programs\Python\Python313\Lib\site-packages\pymongo\synchronous\mongo_client.py", line 1947, in _retry_with_session
    return self._retry_internal(
           ~~~~~~~~~~~~~~~~~~~~^
        func=func,
        ^^^^^^^^^^
    ...<4 lines>...
        operation_id=operation_id,
        ^^^^^^^^^^^^^^^^^^^^^^^^^^
    )
    ^
  File "C:\Users\Joseph\AppData\Local\Programs\Python\Python313\Lib\site-packages\pymongo\_csot.py", line 125, in csot_wrapper
    return func(self, *args, **kwargs)
  File "C:\Users\Joseph\AppData\Local\Programs\Python\Python313\Lib\site-packages\pymongo\synchronous\mongo_client.py", line 1993, in _retry_internal
    ).run()
      ~~~^^
  File "C:\Users\Joseph\AppData\Local\Programs\Python\Python313\Lib\site-packages\pymongo\synchronous\mongo_client.py", line 2730, in run
    return self._read() if self._is_read else self._write()
                                              ~~~~~~~~~~~^^
  File "C:\Users\Joseph\AppData\Local\Programs\Python\Python313\Lib\site-packages\pymongo\synchronous\mongo_client.py", line 2862, in _write
    return self._func(self._session, conn, self._retryable)  # type: ignore
           ~~~~~~~~~~^^^^^^^^^^^^^^^^^^^^^^^^^^^^^^^^^^^^^^
  File "C:\Users\Joseph\AppData\Local\Programs\Python\Python313\Lib\site-packages\pymongo\synchronous\collection.py", line 819, in _insert_command
    result = conn.command(
        self._database.name,
    ...<5 lines>...
        retryable_write=retryable_write,
    )
  File "C:\Users\Joseph\AppData\Local\Programs\Python\Python313\Lib\site-packages\pymongo\synchronous\helpers.py", line 47, in inner
    return func(*args, **kwargs)
  File "C:\Users\Joseph\AppData\Local\Programs\Python\Python313\Lib\site-packages\pymongo\synchronous\pool.py", line 442, in command
    self._raise_connection_failure(error)
    ~~~~~~~~~~~~~~~~~~~~~~~~~~~~~~^^^^^^^
  File "C:\Users\Joseph\AppData\Local\Programs\Python\Python313\Lib\site-packages\pymongo\synchronous\pool.py", line 414, in command
    return command(
        self,
    ...<20 lines>...
        write_concern=write_concern,
    )
  File "C:\Users\Joseph\AppData\Local\Programs\Python\Python313\Lib\site-packages\pymongo\synchronous\network.py", line 148, in command
    request_id, msg, size, max_doc_size = message._op_msg(
                                          ~~~~~~~~~~~~~~~^
        flags, spec, dbname, read_preference, codec_options, ctx=compression_ctx
        ^^^^^^^^^^^^^^^^^^^^^^^^^^^^^^^^^^^^^^^^^^^^^^^^^^^^^^^^^^^^^^^^^^^^^^^^
    )
    ^
  File "C:\Users\Joseph\AppData\Local\Programs\Python\Python313\Lib\site-packages\pymongo\message.py", line 419, in _op_msg
    return _op_msg_uncompressed(flags, command, identifier, docs, opts)
bson.errors.InvalidDocument: Invalid document {'guild_id': 1375913075491737670, 'team_role': 'Team 2', 'channel_name': 'test', 'members': {'1071467618420150414': TeamMember(user_id='1071467618420150414', username='neural_network', display_name='neuron', role_title='Team Member', profile_data={})}, '_team_number': 2, 'created_at': datetime.datetime(2025, 8, 21, 14, 31, 6, 164874), 'updated_at': datetime.datetime(2025, 8, 21, 14, 31, 6, 164878), '_id': ObjectId('68a72daaebff43c25169e35c')} | cannot encode object: TeamMember(user_id='1071467618420150414', username='neural_network', display_name='neuron', role_title='Team Member', profile_data={}), of type: <class 'cogs.teams.models.team.TeamMember'>

The above exception was the direct cause of the following exception:

Traceback (most recent call last):
  File "C:\Users\Joseph\AppData\Local\Programs\Python\Python313\Lib\site-packages\discord\app_commands\tree.py", line 1310, in _call
    await command._invoke_with_namespace(interaction, namespace)
  File "C:\Users\Joseph\AppData\Local\Programs\Python\Python313\Lib\site-packages\discord\app_commands\commands.py", line 883, in _invoke_with_namespace
    return await self._do_call(interaction, transformed_values)
           ^^^^^^^^^^^^^^^^^^^^^^^^^^^^^^^^^^^^^^^^^^^^^^^^^^^^
  File "C:\Users\Joseph\AppData\Local\Programs\Python\Python313\Lib\site-packages\discord\app_commands\commands.py", line 876, in _do_call
    raise CommandInvokeError(self, e) from e
discord.app_commands.errors.CommandInvokeError: Command 'create_team' raised an exception: InvalidDocument: Invalid document {'guild_id': 1375913075491737670, 'team_role': 'Team 2', 'channel_name': 'test', 'members': {'1071467618420150414': TeamMember(user_id='1071467618420150414', username='neural_network', display_name='neuron', role_title='Team Member', profile_data={})}, '_team_number': 2, 'created_at': datetime.datetime(2025, 8, 21, 14, 31, 6, 164874), 'updated_at': datetime.datetime(2025, 8, 21, 14, 31, 6, 164878), '_id': ObjectId('68a72daaebff43c25169e35c')} | cannot encode object: TeamMember(user_id='1071467618420150414', username='neural_network', display_name='neuron', role_title='Team Member', profile_data={}), of type: <class 'cogs.teams.models.team.TeamMember'>
Database manager initialized.
logging in using static token
[31m[1mWARNING: This is a development server. Do not use it in a production deployment. Use a production WSGI server instead.[0m
 * Running on all addresses (0.0.0.0)
 * Running on http://127.0.0.1:8080
 * Running on http://192.168.0.5:8080
[33mPress CTRL+C to quit[0m
Shard ID None has connected to Gateway (Session ID: 8b9a7558642c58c2f18cf45b5802e326).
Bot logged in as Betterment#4897
Bot ID: 1392030134373974066
TeamsCog loaded successfully.
Loaded cog: cogs.teams.cog
Connected to 1 guilds
Synced 6 global commands
An unhandled command error occurred in TeamsCog: Command 'create_team' raised an exception: AttributeError: 'Team' object has no attribute 'to_dict'
Traceback (most recent call last):
  File "C:\Users\Joseph\AppData\Local\Programs\Python\Python313\Lib\site-packages\discord\app_commands\commands.py", line 857, in _do_call
    return await self._callback(self.binding, interaction, **params)  # type: ignore
           ^^^^^^^^^^^^^^^^^^^^^^^^^^^^^^^^^^^^^^^^^^^^^^^^^^^^^^^^^
  File "d:\Home\Documents\Programming\Python\Developer Mode\Discord\Betterment\Bot\cogs\teams\permissions.py", line 66, in wrapper
    return await func(*args, **kwargs)
           ^^^^^^^^^^^^^^^^^^^^^^^^^^^
  File "d:\Home\Documents\Programming\Python\Developer Mode\Discord\Betterment\Bot\cogs\teams\cog.py", line 113, in create_team
    team = await self.team_manager.create_team(interaction.guild, team_number, channel_name, members)
           ^^^^^^^^^^^^^^^^^^^^^^^^^^^^^^^^^^^^^^^^^^^^^^^^^^^^^^^^^^^^^^^^^^^^^^^^^^^^^^^^^^^^^^^^^^
  File "d:\Home\Documents\Programming\Python\Developer Mode\Discord\Betterment\Bot\cogs\teams\services\team_manager.py", line 39, in create_team
    return await self.team_service.create_team(*args, **kwargs)
           ^^^^^^^^^^^^^^^^^^^^^^^^^^^^^^^^^^^^^^^^^^^^^^^^^^^^
  File "d:\Home\Documents\Programming\Python\Developer Mode\Discord\Betterment\Bot\cogs\teams\services\team_service.py", line 44, in create_team
    await self.db.insert_team(team.to_dict())
                              ^^^^^^^^^^^^
AttributeError: 'Team' object has no attribute 'to_dict'

The above exception was the direct cause of the following exception:

Traceback (most recent call last):
  File "C:\Users\Joseph\AppData\Local\Programs\Python\Python313\Lib\site-packages\discord\app_commands\tree.py", line 1310, in _call
    await command._invoke_with_namespace(interaction, namespace)
  File "C:\Users\Joseph\AppData\Local\Programs\Python\Python313\Lib\site-packages\discord\app_commands\commands.py", line 883, in _invoke_with_namespace
    return await self._do_call(interaction, transformed_values)
           ^^^^^^^^^^^^^^^^^^^^^^^^^^^^^^^^^^^^^^^^^^^^^^^^^^^^
  File "C:\Users\Joseph\AppData\Local\Programs\Python\Python313\Lib\site-packages\discord\app_commands\commands.py", line 876, in _do_call
    raise CommandInvokeError(self, e) from e
discord.app_commands.errors.CommandInvokeError: Command 'create_team' raised an exception: AttributeError: 'Team' object has no attribute 'to_dict'
Database manager initialized.
logging in using static token
[31m[1mWARNING: This is a development server. Do not use it in a production deployment. Use a production WSGI server instead.[0m
 * Running on all addresses (0.0.0.0)
 * Running on http://127.0.0.1:8080
 * Running on http://192.168.0.5:8080
[33mPress CTRL+C to quit[0m
Shard ID None has connected to Gateway (Session ID: 1eef4a1fb3648d2f02eef59d8012de09).
Bot logged in as Betterment#4897
Bot ID: 1392030134373974066
TeamsCog loaded successfully.
Loaded cog: cogs.teams.cog
Connected to 1 guilds
Synced 6 global commands
Created team 'Team 2' with 1 members.
Could not find role 'Team 2' to deprovision.
Created team 'Team 3' with 1 members.
Deleted Discord role: Team 1
Deleted Discord channel: #testing
Database manager initialized.
logging in using static token
[31m[1mWARNING: This is a development server. Do not use it in a production deployment. Use a production WSGI server instead.[0m
 * Running on all addresses (0.0.0.0)
 * Running on http://127.0.0.1:8080
 * Running on http://192.168.0.5:8080
[33mPress CTRL+C to quit[0m
Shard ID None has connected to Gateway (Session ID: 1e39d89f657435062b14ce9e1a7ffcc0).
Bot logged in as Betterment#4897
Bot ID: 1392030134373974066
TeamsCog loaded successfully.
Loaded cog: cogs.teams.cog
Connected to 1 guilds
Synced 6 global commands
Could not find role 'Team 2' to deprovision.
Created team 'Team 1' with 1 members.
Database manager initialized.
logging in using static token
[31m[1mWARNING: This is a development server. Do not use it in a production deployment. Use a production WSGI server instead.[0m
 * Running on all addresses (0.0.0.0)
 * Running on http://127.0.0.1:8080
 * Running on http://192.168.0.5:8080
[33mPress CTRL+C to quit[0m
Shard ID None has connected to Gateway (Session ID: 7424249328cb9736e0a85872ea0b378b).
Bot logged in as Betterment#4897
Bot ID: 1392030134373974066
TeamsCog loaded successfully.
Loaded cog: cogs.teams.cog
Connected to 1 guilds
Synced 6 global commands
Created team 'Team 3' with 1 members. Skipped 1 invalid members.
Could not find role 'Team 2' to deprovision.
==================================================
üöÄ STARTING HIERARCHICAL TEAM FORMATION
==================================================
üå± Initializing with 0 leaders and 4 members.
Phase 1: Clustering members by timezone...
-> Found 1 distinct timezone groups.
Phase 2: Clustering by category...
üéØ Initial Clustering Complete: 0 teams created, 4 members initially unassigned.
Phase 4: Reassigning 4 orphaned members...
ü§ù Orphan Reassignment Complete: 0 members placed. 4 remain unassigned.
üö® Final Unassigned Members: ['Luna', 'AgroALT', 'Lotus ü™∑', 'ùêë ùêò ùêé']
==================================================
‚úÖ TEAM FORMATION PROCESS COMPLETE
==================================================
Could not find role 'Team 1' to deprovision.
Could not find role 'Team 2' to deprovision.
Could not find role 'Team 3' to deprovision.
Error in marathon_status command: 'TeamService' object has no attribute 'get_marathon_state_info'
Database manager initialized.
logging in using static token
[31m[1mWARNING: This is a development server. Do not use it in a production deployment. Use a production WSGI server instead.[0m
 * Running on all addresses (0.0.0.0)
 * Running on http://127.0.0.1:8080
 * Running on http://192.168.0.5:8080
[33mPress CTRL+C to quit[0m
Shard ID None has connected to Gateway (Session ID: 36c2ac6ee25637768288670d499b0caa).
Bot logged in as Betterment#4897
Bot ID: 1392030134373974066
TeamsCog loaded successfully.
Loaded cog: cogs.teams.cog
Connected to 1 guilds
Synced 6 global commands
Database manager initialized.
logging in using static token
[31m[1mWARNING: This is a development server. Do not use it in a production deployment. Use a production WSGI server instead.[0m
 * Running on all addresses (0.0.0.0)
 * Running on http://127.0.0.1:8080
 * Running on http://192.168.0.5:8080
[33mPress CTRL+C to quit[0m
Shard ID None has connected to Gateway (Session ID: 4d882abf72b2baa548124190a4708e20).
Bot logged in as Betterment#4897
Bot ID: 1392030134373974066
TeamsCog loaded successfully.
Loaded cog: cogs.teams.cog
Connected to 1 guilds
Synced 6 global commands
Ignoring exception in view <MainPanelView timeout=None children=7> for item <FetchDataButton style=<ButtonStyle.secondary: 2> url=None disabled=False label='Fetch Data' emoji=None row=1 sku_id=None>
Traceback (most recent call last):
  File "C:\Users\Joseph\AppData\Local\Programs\Python\Python313\Lib\site-packages\discord\ui\view.py", line 435, in _scheduled_task
    await item.callback(interaction)
  File "d:\Home\Documents\Programming\Python\Developer Mode\Discord\Betterment\Bot\cogs\teams\permissions.py", line 66, in wrapper
    return await func(*args, **kwargs)
           ^^^^^^^^^^^^^^^^^^^^^^^^^^^
  File "d:\Home\Documents\Programming\Python\Developer Mode\Discord\Betterment\Bot\cogs\teams\ui\buttons.py", line 170, in callback
    await interaction.response.defer(thinking=True, ephemeral=True)
  File "C:\Users\Joseph\AppData\Local\Programs\Python\Python313\Lib\site-packages\discord\interactions.py", line 844, in defer
    response = await adapter.create_interaction_response(
               ^^^^^^^^^^^^^^^^^^^^^^^^^^^^^^^^^^^^^^^^^^
    ...<6 lines>...
    )
    ^
  File "C:\Users\Joseph\AppData\Local\Programs\Python\Python313\Lib\site-packages\discord\webhook\async_.py", line 224, in request
    raise NotFound(response, data)
discord.errors.NotFound: 404 Not Found (error code: 10062): Unknown interaction
Database manager initialized.
logging in using static token
[31m[1mWARNING: This is a development server. Do not use it in a production deployment. Use a production WSGI server instead.[0m
 * Running on all addresses (0.0.0.0)
 * Running on http://127.0.0.1:8080
 * Running on http://192.168.0.5:8080
[33mPress CTRL+C to quit[0m
Shard ID None has connected to Gateway (Session ID: d663463a66d39ff1f32c873599c4225e).
Bot logged in as Betterment#4897
Bot ID: 1392030134373974066
TeamsCog loaded successfully.
Loaded cog: cogs.teams.cog
Connected to 1 guilds
Synced 6 global commands
Error in profile parsing: 'TeamManager' object has no attribute '_get_member_role_title'
Traceback (most recent call last):
  File "d:\Home\Documents\Programming\Python\Developer Mode\Discord\Betterment\Bot\cogs\teams\profile_parsing.py", line 25, in handle_profile_parsing
    role_title = self.team_manager._get_member_role_title(message.author)
                 ^^^^^^^^^^^^^^^^^^^^^^^^^^^^^^^^^^^^^^^^
AttributeError: 'TeamManager' object has no attribute '_get_member_role_title'
